samples/sample_3_10000.csv
A,1,S,284,163
A,2,B,205,138
A,3,S,8,188
X,2,B,205,138
M,1,S,284,163
A,4,B,183,139
A,5,S,142,147
A,6,B,10,158
T,10,147
X,6,B,10,158
M,5,S,132,147
A,7,S,161,138
T,161,138
M,4,B,22,139
X,7,S,161,138
A,8,S,278,141
A,9,B,182,109
A,10,S,123,170
M,9,B,375,109
X,8,S,278,141
A,11,B,339,152
T,132,147
M,11,B,207,152
X,5,S,132,147
M,4,B,22,139
A,12,S,145,184
X,11,B,207,152
A,13,S,108,179
A,14,B,262,136
A,15,S,114,187
A,16,B,31,136
M,10,S,337,170
X,13,S,108,179
A,17,B,207,153
A,18,B,276,168
T,276,163
X,18,B,276,168
M,1,S,8,163
M,9,B,230,134
A,19,B,58,142
X,19,B,58,142
A,20,S,9,150
T,9,150
M,17,B,198,153
X,20,S,9,150
A,21,B,290,112
A,22,B,83,153
X,1,S,8,163
M,22,B,41,153
A,23,B,47,153
X,21,B,290,112
A,24,S,145,176
A,25,S,371,168
A,26,S,353,188
A,27,S,298,161
A,28,S,315,198
A,29,B,222,172
T,222,161
X,29,B,222,172
M,27,S,76,161
A,30,B,94,123
A,31,B,389,177
T,76,161
T,313,168
M,31,B,313,177
X,27,S,76,161
X,31,B,313,177
M,25,S,58,168
A,32,S,188,175
X,12,S,145,184
X,32,S,188,175
A,33,B,183,176
T,58,168
T,125,170
M,33,B,125,176
X,25,S,58,168
X,33,B,125,176
M,10,S,212,170
A,34,B,137,125
X,28,S,315,198
X,10,S,212,170
X,15,S,114,187
M,23,B,47,153
A,35,B,192,181
T,145,176
M,35,B,47,181
X,24,S,145,176
A,36,B,399,183
A,37,B,29,175
A,38,B,345,136
A,39,B,335,198
T,8,188
T,327,188
M,39,B,327,198
X,3,S,8,188
X,39,B,327,198
M,26,S,26,188
A,40,B,64,151
A,41,B,137,188
T,26,188
M,41,B,111,188
X,26,S,26,188
M,41,B,117,215
A,42,S,64,245
X,42,S,64,245
A,43,S,368,235
M,16,B,31,136
A,44,B,124,199
A,45,S,353,241
A,46,S,250,289
M,43,S,368,235
A,47,S,43,288
A,48,B,115,229
M,47,S,87,206
T,87,206
M,48,B,28,229
X,47,S,87,206
M,46,S,112,230
M,22,B,335,170
A,49,S,164,275
M,30,B,342,123
M,49,S,56,237
X,48,B,28,229
M,43,S,207,235
A,50,B,207,253
T,112,230
T,95,235
M,50,B,95,253
X,46,S,112,230
X,50,B,95,253
M,43,S,112,235
A,51,B,30,184
A,52,B,145,163
A,53,S,28,222
M,36,B,399,160
X,43,S,112,235
A,54,B,392,210
A,55,B,248,197
M,16,B,320,136
A,56,B,13,174
M,36,B,399,160
M,34,B,137,125
X,4,B,22,139
M,45,S,157,254
A,57,B,298,196
M,17,B,198,230
T,28,222
M,17,B,170,230
X,53,S,28,222
A,58,S,256,226
T,170,226
X,17,B,170,230
M,58,S,86,226
A,59,S,111,187
T,111,187
M,41,B,6,215
X,59,S,111,187
A,60,B,308,224
A,61,B,17,164
M,52,B,145,163
M,45,S,157,198
T,157,198
M,60,B,151,224
X,45,S,157,198
A,62,S,50,289
A,63,S,254,276
A,64,B,134,244
T,86,226
T,48,237
M,64,B,48,244
X,58,S,86,226
X,64,B,48,244
M,49,S,8,237
X,62,S,50,289
A,65,B,319,251
T,8,237
M,65,B,311,251
X,49,S,8,237
A,66,B,269,269
A,67,B,137,286
T,137,276
X,67,B,137,286
M,63,S,117,276
X,22,B,335,170
A,68,S,22,345
M,63,S,117,234
T,117,234
M,66,B,152,269
X,63,S,117,234
X,23,B,47,153
A,69,S,295,359
A,70,B,173,284
A,71,S,361,375
M,68,S,101,394
A,72,S,390,398
A,73,B,46,303
A,74,S,359,307
A,75,S,30,374
A,76,S,18,326
A,77,B,394,299
A,78,B,247,300
A,79,S,218,356
M,69,S,295,321
A,80,S,36,320
A,81,B,22,227
X,74,S,359,307
A,82,B,66,248
A,83,B,330,254
A,84,B,353,343
T,36,320
T,295,321
T,18,326
M,84,B,317,343
X,80,S,36,320
M,84,B,22,343
X,69,S,295,321
M,84,B,4,343
X,76,S,18,326
M,68,S,273,438
M,34,B,137,282
X,79,S,218,356
A,85,S,122,384
A,86,S,30,311
T,4,311
X,84,B,4,343
M,86,S,26,311
A,87,B,293,268
M,85,S,230,308
A,88,B,241,289
A,89,B,379,270
A,90,B,343,219
X,89,B,379,270
X,75,S,30,374
A,91,B,186,220
A,92,B,216,267
A,93,S,230,381
X,87,B,293,268
A,94,S,248,381
A,95,B,308,258
M,60,B,151,224
M,85,S,242,308
A,96,S,171,355
M,96,S,171,373
A,97,B,116,338
T,116,308
X,97,B,116,338
M,85,S,126,308
X,16,B,320,136
X,90,B,343,219
M,30,B,282,336
T,126,308
T,26,311
M,30,B,156,336
X,85,S,126,308
M,30,B,130,336
X,86,S,26,311
A,98,B,288,273
X,35,B,47,181
X,83,B,330,254
A,99,B,306,293
A,100,B,198,255
A,101,S,36,408
A,102,B,170,272
A,103,B,221,387
T,171,373
T,50,375
M,103,B,50,387
X,96,S,171,373
X,103,B,50,387
M,71,S,311,375
M,101,S,30,352
A,104,S,249,313
T,130,313
X,30,B,130,336
M,104,S,119,313
X,101,S,30,352
A,105,S,183,338
A,106,B,305,255
X,55,B,248,197
A,107,S,370,283
T,46,283
T,247,283
T,77,283
X,73,B,46,303
M,107,S,324,283
X,78,B,247,300
M,107,S,77,283
M,77,B,317,299
X,107,S,77,283
X,37,B,29,175
A,108,B,38,283
X,105,S,183,338
M,71,S,311,377
A,109,S,249,336
M,108,B,391,268
A,110,S,286,279
T,286,279
M,77,B,31,299
X,110,S,286,279
A,111,B,358,305
A,112,S,338,264
T,338,264
M,111,B,20,305
X,112,S,338,264
A,113,B,294,336
T,119,313
T,175,336
M,113,B,175,336
X,104,S,119,313
X,113,B,175,336
M,109,S,74,336
A,114,B,119,279
A,115,S,314,304
T,20,304
X,111,B,20,305
M,115,S,294,304
A,116,B,253,220
A,117,S,43,343
X,92,B,216,267
A,118,B,314,327
T,294,304
M,118,B,20,327
X,115,S,294,304
A,119,S,376,294
T,20,294
T,31,294
X,118,B,20,327
M,119,S,356,294
X,77,B,31,299
M,119,S,325,294
A,120,B,197,335
T,197,294
X,120,B,197,335
M,119,S,128,294
X,93,S,230,381
M,54,B,108,317
T,108,294
X,54,B,108,317
M,119,S,20,294
A,121,S,130,356
M,14,B,205,222
A,122,B,258,250
M,61,B,17,265
M,95,B,308,258
A,123,S,362,373
M,52,B,145,163
A,124,B,220,239
A,125,S,334,259
T,306,259
T,28,259
X,99,B,306,293
M,125,S,28,259
M,88,B,213,289
X,125,S,28,259
A,126,B,213,313
T,20,294
M,126,B,193,313
X,119,S,20,294
A,127,S,311,355
M,44,B,336,199
A,128,S,352,290
T,193,290
X,126,B,193,313
M,128,S,159,290
A,129,B,176,291
T,159,290
M,129,B,17,291
X,128,S,159,290
A,130,B,212,340
T,74,336
M,130,B,138,340
X,109,S,74,336
A,131,S,73,317
T,73,317
M,130,B,65,340
X,131,S,73,317
M,117,S,43,357
A,132,B,392,360
T,311,355
T,81,356
M,132,B,81,360
X,127,S,311,355
X,132,B,81,360
M,121,S,49,356
A,133,S,264,359
A,134,S,301,319
T,65,319
X,130,B,65,340
M,134,S,236,319
A,135,B,197,252
M,68,S,119,438
M,66,B,366,269
A,136,S,360,361
A,137,B,114,236
M,114,B,272,310
A,138,B,42,240
A,139,S,392,324
A,140,B,196,358
T,196,319
X,140,B,196,358
M,134,S,40,319
M,94,S,248,381
X,100,B,198,255
M,116,B,253,340
T,40,319
T,213,324
M,116,B,213,340
X,134,S,40,319
X,116,B,213,340
M,139,S,179,324
X,139,S,179,324
A,141,B,226,263
X,136,S,360,361
A,142,B,350,354
A,143,B,370,383
T,49,356
T,43,357
T,264,359
T,14,373
M,143,B,321,383
X,121,S,49,356
M,143,B,278,383
X,117,S,43,357
M,143,B,14,383
X,133,S,264,359
X,143,B,14,383
M,123,S,348,373
A,144,B,330,413
T,330,373
X,144,B,330,413
M,123,S,18,373
X,51,B,30,184
A,145,S,351,411
A,146,S,386,374
X,146,S,386,374
A,147,B,167,361
X,34,B,137,282
A,148,B,210,323
A,149,S,202,422
A,150,B,175,312
M,149,S,202,422
A,151,S,226,427
A,152,B,101,270
A,153,B,348,301
M,68,S,100,429
A,154,B,377,406
T,18,373
T,311,377
T,48,381
M,154,B,359,406
X,123,S,18,373
M,154,B,48,406
X,71,S,311,377
X,154,B,48,406
M,94,S,200,381
A,155,B,128,290
A,156,S,330,431
A,157,S,28,363
A,158,S,268,441
A,159,S,204,342
T,167,342
T,37,342
X,147,B,167,361
M,159,S,37,342
M,142,B,313,354
X,159,S,37,342
M,60,B,151,224
X,149,S,202,422
A,160,S,40,329
T,40,329
M,142,B,273,354
X,160,S,40,329
A,161,S,380,362
A,162,S,59,401
X,61,B,17,265
A,163,B,310,321
A,164,S,283,412
A,165,S,41,340
T,41,340
M,142,B,232,354
X,165,S,41,340
M,9,B,230,134
A,166,S,113,314
T,113,314
M,142,B,119,354
X,166,S,113,314
X,164,S,283,412
A,167,B,257,352
A,168,B,301,303
A,169,S,301,319
T,119,319
T,182,319
X,142,B,119,354
M,169,S,182,319
M,167,B,75,352
X,169,S,182,319
A,170,B,163,398
T,163,362
X,170,B,163,398
M,161,S,217,362
X,162,S,59,401
X,137,B,114,236
A,171,S,260,321
T,75,321
T,185,321
X,167,B,75,352
M,171,S,185,321
M,148,B,25,323
X,171,S,185,321
A,172,S,128,315
T,25,315
T,103,315
X,148,B,25,323
M,172,S,103,315
M,163,B,207,321
X,172,S,103,315
A,173,S,307,296
T,207,296
T,100,296
X,163,B,207,321
M,173,S,100,296
M,150,B,75,312
X,173,S,100,296
A,174,B,141,356
M,156,S,330,346
T,141,346
X,174,B,141,356
M,156,S,189,346
A,175,S,216,363
A,176,S,178,367
M,70,B,112,272
X,88,B,213,289
A,177,B,186,296
M,158,S,268,441
M,175,S,3,342
M,168,B,301,353
T,3,342
T,189,346
M,168,B,298,353
X,175,S,3,342
M,168,B,109,353
X,156,S,189,346
A,178,B,345,280
X,81,B,22,227
M,124,B,220,253
A,179,B,70,270
A,180,B,146,332
M,70,B,125,273
A,181,B,136,354
A,182,S,187,335
T,136,335
T,51,335
X,181,B,136,354
M,182,S,51,335
M,168,B,58,353
X,182,S,51,335
M,60,B,92,224
X,161,S,217,362
A,183,S,109,417
A,184,S,314,460
X,157,S,28,363
X,129,B,17,291
A,185,S,218,464
A,186,S,287,457
A,187,B,136,355
